<?xml version="1.0"?>
<robot name="example_robot_2">
  <!-- Base Link -->
  <link name="base_link">
    <visual>
      <geometry>
        <cylinder length="0.15" radius="0.25"/>
      </geometry>
      <material name="dark_gray">
        <color rgba="0.2 0.2 0.2 1"/>
      </material>
    </visual>
    <collision>
      <geometry>
        <cylinder length="0.15" radius="0.25"/>
      </geometry>
    </collision>
    <inertial>
      <mass value="8"/>
      <inertia ixx="0.15" ixy="0" ixz="0" iyy="0.15" iyz="0" izz="0.15"/>
    </inertial>
  </link>

  <!-- Joint 1: Base to Column -->
  <joint name="base_to_column" type="revolute">
    <parent link="base_link"/>
    <child link="column_link"/>
    <origin xyz="0 0 0.075" rpy="0 0 0"/>
    <axis xyz="0 0 1"/>
    <limit lower="-3.14" upper="3.14" effort="150" velocity="1.5"/>
  </joint>

  <!-- Column Link -->
  <link name="column_link">
    <visual>
      <geometry>
        <cylinder length="0.5" radius="0.1"/>
      </geometry>
      <material name="silver">
        <color rgba="0.8 0.8 0.8 1"/>
      </material>
    </visual>
    <collision>
      <geometry>
        <cylinder length="0.5" radius="0.1"/>
      </geometry>
    </collision>
    <inertial>
      <mass value="5"/>
      <inertia ixx="0.1" ixy="0" ixz="0" iyy="0.1" iyz="0" izz="0.05"/>
    </inertial>
  </link>

  <!-- Joint 2: Column to Lift (Prismatic) -->
  <joint name="column_to_lift" type="prismatic">
    <parent link="column_link"/>
    <child link="lift_link"/>
    <origin xyz="0 0 0.25" rpy="0 0 0"/>
    <axis xyz="0 0 1"/>
    <limit lower="0" upper="0.4" effort="100" velocity="0.5"/>
  </joint>

  <!-- Lift Link -->
  <link name="lift_link">
    <visual>
      <geometry>
        <box size="0.15 0.15 0.1"/>
      </geometry>
      <material name="blue">
        <color rgba="0 0 0.8 1"/>
      </material>
    </visual>
    <collision>
      <geometry>
        <box size="0.15 0.15 0.1"/>
      </geometry>
    </collision>
    <inertial>
      <mass value="3"/>
      <inertia ixx="0.03" ixy="0" ixz="0" iyy="0.03" iyz="0" izz="0.03"/>
    </inertial>
  </link>

  <!-- Joint 3: Lift to Shoulder -->
  <joint name="lift_to_shoulder" type="revolute">
    <parent link="lift_link"/>
    <child link="shoulder_link"/>
    <origin xyz="0 0 0.05" rpy="0 0 0"/>
    <axis xyz="0 1 0"/>
    <limit lower="-1.57" upper="1.57" effort="120" velocity="1.2"/>
  </joint>

  <!-- Shoulder Link -->
  <link name="shoulder_link">
    <visual>
      <geometry>
        <box size="0.12 0.12 0.12"/>
      </geometry>
      <material name="red">
        <color rgba="0.8 0 0 1"/>
      </material>
    </visual>
    <collision>
      <geometry>
        <box size="0.12 0.12 0.12"/>
      </geometry>
    </collision>
    <inertial>
      <mass value="2"/>
      <inertia ixx="0.02" ixy="0" ixz="0" iyy="0.02" iyz="0" izz="0.02"/>
    </inertial>
  </link>

  <!-- Joint 4: Shoulder to Upper Arm -->
  <joint name="shoulder_to_upper_arm" type="revolute">
    <parent link="shoulder_link"/>
    <child link="upper_arm_link"/>
    <origin xyz="0 0 0.06" rpy="0 0 0"/>
    <axis xyz="0 1 0"/>
    <limit lower="-1.57" upper="1.57" effort="100" velocity="1"/>
  </joint>

  <!-- Upper Arm Link -->
  <link name="upper_arm_link">
    <visual>
      <geometry>
        <cylinder length="0.45" radius="0.06"/>
      </geometry>
      <material name="green">
        <color rgba="0 0.8 0 1"/>
      </material>
    </visual>
    <collision>
      <geometry>
        <cylinder length="0.45" radius="0.06"/>
      </geometry>
    </collision>
    <inertial>
      <mass value="2.5"/>
      <inertia ixx="0.025" ixy="0" ixz="0" iyy="0.025" iyz="0" izz="0.025"/>
    </inertial>
  </link>

  <!-- Joint 5: Upper Arm to Elbow -->
  <joint name="upper_arm_to_elbow" type="revolute">
    <parent link="upper_arm_link"/>
    <child link="elbow_link"/>
    <origin xyz="0 0 0.225" rpy="0 0 0"/>
    <axis xyz="0 1 0"/>
    <limit lower="-1.57" upper="1.57" effort="100" velocity="1.2"/>
  </joint>

  <!-- Elbow Link -->
  <link name="elbow_link">
    <visual>
      <geometry>
        <box size="0.1 0.1 0.1"/>
      </geometry>
      <material name="yellow">
        <color rgba="0.8 0.8 0 1"/>
      </material>
    </visual>
    <collision>
      <geometry>
        <box size="0.1 0.1 0.1"/>
      </geometry>
    </collision>
    <inertial>
      <mass value="1.5"/>
      <inertia ixx="0.015" ixy="0" ixz="0" iyy="0.015" iyz="0" izz="0.015"/>
    </inertial>
  </link>

  <!-- Joint 6: Elbow to Forearm -->
  <joint name="elbow_to_forearm" type="revolute">
    <parent link="elbow_link"/>
    <child link="forearm_link"/>
    <origin xyz="0 0 0.05" rpy="0 0 0"/>
    <axis xyz="0 1 0"/>
    <limit lower="-1.57" upper="1.57" effort="80" velocity="1.5"/>
  </joint>

  <!-- Forearm Link -->
  <link name="forearm_link">
    <visual>
      <geometry>
        <cylinder length="0.35" radius="0.05"/>
      </geometry>
      <material name="purple">
        <color rgba="0.8 0 0.8 1"/>
      </material>
    </visual>
    <collision>
      <geometry>
        <cylinder length="0.35" radius="0.05"/>
      </geometry>
    </collision>
    <inertial>
      <mass value="2"/>
      <inertia ixx="0.02" ixy="0" ixz="0" iyy="0.02" iyz="0" izz="0.02"/>
    </inertial>
  </link>

  <!-- Joint 7: Forearm to Wrist -->
  <joint name="forearm_to_wrist" type="revolute">
    <parent link="forearm_link"/>
    <child link="wrist_link"/>
    <origin xyz="0 0 0.175" rpy="0 0 0"/>
    <axis xyz="0 0 1"/>
    <limit lower="-3.14" upper="3.14" effort="60" velocity="2.5"/>
  </joint>

  <!-- Wrist Link -->
  <link name="wrist_link">
    <visual>
      <geometry>
        <box size="0.1 0.1 0.1"/>
      </geometry>
      <material name="cyan">
        <color rgba="0 0.8 0.8 1"/>
      </material>
    </visual>
    <collision>
      <geometry>
        <box size="0.1 0.1 0.1"/>
      </geometry>
    </collision>
    <inertial>
      <mass value="1"/>
      <inertia ixx="0.01" ixy="0" ixz="0" iyy="0.01" iyz="0" izz="0.01"/>
    </inertial>
  </link>

  <!-- Joint 8: Wrist to End Effector -->
  <joint name="wrist_to_end_effector" type="revolute">
    <parent link="wrist_link"/>
    <child link="end_effector_link"/>
    <origin xyz="0 0 0.05" rpy="0 0 0"/>
    <axis xyz="1 0 0"/>
    <limit lower="-1.57" upper="1.57" effort="40" velocity="3"/>
  </joint>

  <!-- End Effector Link (with camera and gripper) -->
  <link name="end_effector_link">
    <visual>
      <geometry>
        <box size="0.08 0.15 0.08"/>
      </geometry>
      <material name="white">
        <color rgba="1 1 1 1"/>
      </material>
    </visual>
    <collision>
      <geometry>
        <box size="0.08 0.15 0.08"/>
      </geometry>
    </collision>
    <inertial>
      <mass value="0.8"/>
      <inertia ixx="0.008" ixy="0" ixz="0" iyy="0.008" iyz="0" izz="0.008"/>
    </inertial>
  </link>
</robot>