<?xml version="1.0"?>
<robot name="example_robot_1">
  <!-- Base Link -->
  <link name="base_link">
    <visual>
      <geometry>
        <cylinder length="0.1" radius="0.2"/>
      </geometry>
      <material name="blue">
        <color rgba="0 0 0.8 1"/>
      </material>
    </visual>
    <collision>
      <geometry>
        <cylinder length="0.1" radius="0.2"/>
      </geometry>
    </collision>
    <inertial>
      <mass value="5"/>
      <inertia ixx="0.1" ixy="0" ixz="0" iyy="0.1" iyz="0" izz="0.1"/>
    </inertial>
  </link>

  <!-- Joint 1: Base to Shoulder -->
  <joint name="base_to_shoulder" type="revolute">
    <parent link="base_link"/>
    <child link="shoulder_link"/>
    <origin xyz="0 0 0.1" rpy="0 0 0"/>
    <axis xyz="0 0 1"/>
    <limit lower="-3.14" upper="3.14" effort="100" velocity="1"/>
  </joint>

  <!-- Shoulder Link -->
  <link name="shoulder_link">
    <visual>
      <geometry>
        <box size="0.1 0.1 0.1"/>
      </geometry>
      <material name="red">
        <color rgba="0.8 0 0 1"/>
      </material>
    </visual>
    <collision>
      <geometry>
        <box size="0.1 0.1 0.1"/>
      </geometry>
    </collision>
    <inertial>
      <mass value="1"/>
      <inertia ixx="0.01" ixy="0" ixz="0" iyy="0.01" iyz="0" izz="0.01"/>
    </inertial>
  </link>

  <!-- Joint 2: Shoulder to Upper Arm -->
  <joint name="shoulder_to_upper_arm" type="revolute">
    <parent link="shoulder_link"/>
    <child link="upper_arm_link"/>
    <origin xyz="0 0 0.1" rpy="0 0 0"/>
    <axis xyz="0 1 0"/>
    <limit lower="-1.57" upper="1.57" effort="100" velocity="1"/>
  </joint>

  <!-- Upper Arm Link -->
  <link name="upper_arm_link">
    <visual>
      <geometry>
        <cylinder length="0.4" radius="0.05"/>
      </geometry>
      <material name="green">
        <color rgba="0 0.8 0 1"/>
      </material>
    </visual>
    <collision>
      <geometry>
        <cylinder length="0.4" radius="0.05"/>
      </geometry>
    </collision>
    <inertial>
      <mass value="2"/>
      <inertia ixx="0.02" ixy="0" ixz="0" iyy="0.02" iyz="0" izz="0.02"/>
    </inertial>
  </link>

  <!-- Joint 3: Upper Arm to Elbow -->
  <joint name="upper_arm_to_elbow" type="revolute">
    <parent link="upper_arm_link"/>
    <child link="elbow_link"/>
    <origin xyz="0 0 0.2" rpy="0 0 0"/>
    <axis xyz="0 1 0"/>
    <limit lower="-1.57" upper="1.57" effort="100" velocity="1"/>
  </joint>

  <!-- Elbow Link -->
  <link name="elbow_link">
    <visual>
      <geometry>
        <box size="0.1 0.1 0.1"/>
      </geometry>
      <material name="yellow">
        <color rgba="0.8 0.8 0 1"/>
      </material>
    </visual>
    <collision>
      <geometry>
        <box size="0.1 0.1 0.1"/>
      </geometry>
    </collision>
    <inertial>
      <mass value="1"/>
      <inertia ixx="0.01" ixy="0" ixz="0" iyy="0.01" iyz="0" izz="0.01"/>
    </inertial>
  </link>

  <!-- Joint 4: Elbow to Forearm -->
  <joint name="elbow_to_forearm" type="revolute">
    <parent link="elbow_link"/>
    <child link="forearm_link"/>
    <origin xyz="0 0 0.1" rpy="0 0 0"/>
    <axis xyz="0 1 0"/>
    <limit lower="-1.57" upper="1.57" effort="100" velocity="1"/>
  </joint>

  <!-- Forearm Link -->
  <link name="forearm_link">
    <visual>
      <geometry>
        <cylinder length="0.3" radius="0.04"/>
      </geometry>
      <material name="purple">
        <color rgba="0.8 0 0.8 1"/>
      </material>
    </visual>
    <collision>
      <geometry>
        <cylinder length="0.3" radius="0.04"/>
      </geometry>
    </collision>
    <inertial>
      <mass value="1.5"/>
      <inertia ixx="0.015" ixy="0" ixz="0" iyy="0.015" iyz="0" izz="0.015"/>
    </inertial>
  </link>

  <!-- Joint 5: Forearm to Wrist -->
  <joint name="forearm_to_wrist" type="revolute">
    <parent link="forearm_link"/>
    <child link="wrist_link"/>
    <origin xyz="0 0 0.15" rpy="0 0 0"/>
    <axis xyz="0 0 1"/>
    <limit lower="-3.14" upper="3.14" effort="50" velocity="2"/>
  </joint>

  <!-- Wrist Link -->
  <link name="wrist_link">
    <visual>
      <geometry>
        <box size="0.08 0.08 0.08"/>
      </geometry>
      <material name="cyan">
        <color rgba="0 0.8 0.8 1"/>
      </material>
    </visual>
    <collision>
      <geometry>
        <box size="0.08 0.08 0.08"/>
      </geometry>
    </collision>
    <inertial>
      <mass value="0.5"/>
      <inertia ixx="0.005" ixy="0" ixz="0" iyy="0.005" iyz="0" izz="0.005"/>
    </inertial>
  </link>

  <!-- Joint 6: Wrist to Gripper -->
  <joint name="wrist_to_gripper" type="revolute">
    <parent link="wrist_link"/>
    <child link="gripper_link"/>
    <origin xyz="0 0 0.04" rpy="0 0 0"/>
    <axis xyz="1 0 0"/>
    <limit lower="-1.57" upper="1.57" effort="30" velocity="3"/>
  </joint>

  <!-- Gripper Link -->
  <link name="gripper_link">
    <visual>
      <geometry>
        <box size="0.05 0.1 0.05"/>
      </geometry>
      <material name="white">
        <color rgba="1 1 1 1"/>
      </material>
    </visual>
    <collision>
      <geometry>
        <box size="0.05 0.1 0.05"/>
      </geometry>
    </collision>
    <inertial>
      <mass value="0.3"/>
      <inertia ixx="0.003" ixy="0" ixz="0" iyy="0.003" iyz="0" izz="0.003"/>
    </inertial>
  </link>
</robot>